Workbook

Sheet 0. Legenda
A1: Plano HIIP - legenda e convenções
A3: Níveis
A4: Projeto | B4: O programa maior. Nesta planilha, apenas o HIIP.
A5: Frente de trabalho (produto) | B5: A frente que produz um produto. É o nível onde vive a validação externa. Cada frente tem a sua aba própria.
A6: Resultado (output) | B6: Entrega intermédia que fecha dentro de uma ou duas sprints. É o nível onde vive a definição de feito.
A7: Tarefa | B7: O trabalho concreto. Não tem critério próprio: está feita ou não está.
A9: Definição de feito e validação
A10: Definição de feito | B10: Critérios internos do resultado, sob o teu controlo. O resultado fecha quando são cumpridos.
A11: Validação externa | B11: Aceitação pelo cliente (TWG-PHC, TWG-PFM, Ministra, financiadores). Existe só ao nível da frente, tem data própria e não está sob o teu controlo.
A12: Tarefas sem resultado | B12: Linhas com o campo Resultado vazio: tarefas que servem diretamente a validação externa da frente.
A14: Definição de feito geral - aplica-se a todos os resultados
A15: 1 | B15: Revisto por ti numa segunda passagem, em dia diferente do da redação.
A16: 2 | B16: Toda afirmação sobre um documento tem referência de página verificável.
A17: 3 | B17: Fontes de dados identificadas, com data de extração.
A18: 4 | B18: Estruturado pelas alavancas do operational framework de CSP da OMS, quando aplicável.
A19: 5 | B19: Versão datada, guardada na biblioteca do SharePoint, com o link registado.
A20: 6 | B20: Revisão do country office sempre que o resultado sai do escritório.
A21: 7 | B21: Português como versão base; inglês quando se destina a parceiros.
A23: Estados
A24: Tarefa | B24: Backlog (identificada) - To do (comprometida para a sprint) - In progress - Blocked (parada por terceiros) - Done.
A25: Resultado | B25: Não iniciado - Em curso - Feito.
A26: Validação | B26: Não iniciada - Em curso - Feita.
A28: Outras colunas
A29: Sprint | B29: Quinzena prevista. Datas na aba Sprints. 'Recorrente' repete-se em todas; 'TBC' aguarda data.
A30: Estimativa | B30: Dias de trabalho. Primeira aproximação, para ser corrigida com o uso.
A31: Depende de | B31: O que tem de estar concluído antes. Se não estiver, a tarefa fica Blocked, não atrasada.
A32: Aprendizado | B32: Informação crítica surgida ao realizar a tarefa: consequências, dados novos, problemas reconhecidos. Preenche-se ao fazer e revê-se na retrospetiva de fecho de sprint.
A34: Abas
A35: 1. Frentes | B35: Uma linha por frente, com validação externa e contagem automática de progresso.
A36: 2. Master | B36: Todas as linhas do plano: frente, resultado, tarefa. É a fonte de verdade.
A37: 3. Tarefas | B37: Backlog plano, ordenado por sprint. Para o planeamento de cada quinzena.
A38: 4. Sprints | B38: Calendário quinzenal de 3 de agosto de 2026 a 2 de julho de 2027.
A39: 5 e seguintes | B39: Uma aba por frente, com o mesmo conteúdo filtrado.
A41: Regra de promoção
B42: Aprendizado que muda o plano não fica só na coluna: vira alteração da definição de feito, tarefa nova ou linha no registo de riscos.

Sheet 1. Frentes
A1: Frentes do HIIP
A3: Frente de trabalho (produto) | B3: Validação externa | C3: Data validação | D3: Estado validação | E3: Resultados | F3: Tarefas | G3: Tarefas feitas | H3: % feito | I3: Aba
A4: TWG-PHC | B4: Autoridades autorizam formalmente a reconstituição do grupo; sessão de refundação realizada com quórum; plano de atividades aceite pelos membros | C4: 46318 | D4: Não iniciada | E4: 1 | F4: 8 | G4: =COUNTIFS('2. Master'!$B$4:$B$162,$A4,'2. Master'!$O$4:$O$162,"Done") -> 0 | H4: =IFERROR($G4/$F4,0) -> 0 | I4: 1. TWG-PHC
A5: Background document - PHC | B5: Apresentado ao TWG-PHC; posição registada sobre o diagnóstico; ata com comentários e responsáveis; alterações incorporadas em versão datada | C5: 46332 | D5: Não iniciada | E5: 7 | F5: 31 | G5: =COUNTIFS('2. Master'!$B$4:$B$162,$A5,'2. Master'!$O$4:$O$162,"Done") -> 4 | H5: =IFERROR($G5/$F5,0) -> 0.12903226 | I5: 2. Background document
A6: Strategy document - PHC | B6: Apresentada ao TWG-PHC; posição registada sobre cada área priorizada (aceite/alterada/rejeitada); ata com decisões e responsáveis; MINSA confirma que serve de documento de política habilitante; alterações acordadas incorporadas em versão datada | C6: 46346 | D6: Não iniciada | E6: 3 | F6: 9 | G6: =COUNTIFS('2. Master'!$B$4:$B$162,$A6,'2. Master'!$O$4:$O$162,"Done") -> 0 | H6: =IFERROR($G6/$F6,0) -> 0 | I6: 3. Strategy document
A7: HHFA e diagnóstico situacional | B7: Relatório do HHFA apresentado e aceite; mecanismo rotineiro de avaliação estrutural proposto ao MINSA | C7: 46542 | D7: Não iniciada | E7: 7 | F7: 22 | G7: =COUNTIFS('2. Master'!$B$4:$B$162,$A7,'2. Master'!$O$4:$O$162,"Done") -> 0 | H7: =IFERROR($G7/$F7,0) -> 0 | I7: 4. HHFA
A8: PFM | B8: Diagnóstico apresentado ao TWG-PFM; posição registada; ata com decisões; alterações incorporadas em versão datada | C8: 46444 | D8: Não iniciada | E8: 4 | F8: 20 | G8: =COUNTIFS('2. Master'!$B$4:$B$162,$A8,'2. Master'!$O$4:$O$162,"Done") -> 2 | H8: =IFERROR($G8/$F8,0) -> 0.1 | I8: 5. PFM
A9: Investment case - PHC | B9: Duas validações: diálogo no MINSA com a Ministra sobre a v1 (06/11/2026); validação técnica da v2, com HHFA, pelo TWG-PHC (26/02/2027) | C9: 46444 | D9: Não iniciada | E9: 4 | F9: 13 | G9: =COUNTIFS('2. Master'!$B$4:$B$162,$A9,'2. Master'!$O$4:$O$162,"Done") -> 0 | H9: =IFERROR($G9/$F9,0) -> 0 | I9: 6. Investment case
A10: PHC investment plan (custeado) | B10: Plano validado pelo TWG-PHC; posição registada; alterações incorporadas em versão datada | C10: 46472 | D10: Não iniciada | E10: 5 | F10: 15 | G10: =COUNTIFS('2. Master'!$B$4:$B$162,$A10,'2. Master'!$O$4:$O$162,"Done") -> 0 | H10: =IFERROR($G10/$F10,0) -> 0 | I10: 7. Investment plan
A11: Essential package - PHC | B11: Pacote essencial apresentado ao TWG-PHC; posição registada; alterações incorporadas em versão datada | C11: 46402 | D11: Não iniciada | E11: 4 | F11: 9 | G11: =COUNTIFS('2. Master'!$B$4:$B$162,$A11,'2. Master'!$O$4:$O$162,"Done") -> 0 | H11: =IFERROR($G11/$F11,0) -> 0 | I11: 8. Essential package
A12: Modelo de cuidados e perfis profissionais - PHC | B12: Modelo apresentado ao TWG-PHC; posição registada; alterações incorporadas em versão datada | C12: 46402 | D12: Não iniciada | E12: 4 | F12: 13 | G12: =COUNTIFS('2. Master'!$B$4:$B$162,$A12,'2. Master'!$O$4:$O$162,"Done") -> 0 | H12: =IFERROR($G12/$F12,0) -> 0 | I12: 9. Modelo de cuidados
A13: Project scoping - PHC | B13: Project profiles revistos com o MINSA e os financiadores potenciais | C13: 46500 | D13: Não iniciada | E13: 2 | F13: 6 | G13: =COUNTIFS('2. Master'!$B$4:$B$162,$A13,'2. Master'!$O$4:$O$162,"Done") -> 0 | H13: =IFERROR($G13/$F13,0) -> 0 | I13: 10. Project scoping
A14: Mobilização de financiamento - PHC | B14: Compromissos de financiadores registados; proposta de empréstimo assinada | C14: 46556 | D14: Não iniciada | E14: 2 | F14: 8 | G14: =COUNTIFS('2. Master'!$B$4:$B$162,$A14,'2. Master'!$O$4:$O$162,"Done") -> 0 | H14: =IFERROR($G14/$F14,0) -> 0 | I14: 11. Financiamento
A15: Relatórios contratuais do HIIP | E15: 2 | F15: 5 | G15: =COUNTIFS('2. Master'!$B$4:$B$162,$A15,'2. Master'!$O$4:$O$162,"Done") -> 0 | H15: =IFERROR($G15/$F15,0) -> 0 | I15: 12. Relatórios
A16: TOTAL | E16: =SUM(E4:E15) -> 45 | F16: =SUM(F4:F15) -> 159 | G16: =SUM(G4:G15) -> 6 | H16: =IFERROR(G16/F16,0) -> 0.037735849

Sheet 2. Master
A1: Master - todas as frentes, resultados e tarefas do HIIP
A3: Projeto | B3: Frente de trabalho (produto) | C3: Validação externa | D3: Data validação | E3: Estado validação | F3: Resultado (output) | G3: Definição de feito (resultado) | H3: Data resultado | I3: Estado resultado | J3: Tarefa | K3: Sprint | L3: Responsável | M3: Estimativa (dias) | N3: Depende de | O3: Estado tarefa | P3: Aprendizado
A4: HIIP | B4: TWG-PHC | C4: Autoridades autorizam formalmente a reconstituição do grupo; sessão de refundação realizada com quórum; plano de atividades aceite pelos membros | D4: 46318 | E4: Não iniciada | F4: Proposta de reconstituição do TWG-PHC | G4: Lista de atores anteriores identificada; lacunas de representação identificadas; plano de atividades redigido; convites e pedido de autorização preparados | H4: 46304 | I4: Não iniciado | J4: Identificar os atores anteriormente convocados | K4: S3 | L4: AGJ | M4: 2 | O4: Backlog
A5: HIIP | B5: TWG-PHC | C5: Autoridades autorizam formalmente a reconstituição do grupo; sessão de refundação realizada com quórum; plano de atividades aceite pelos membros | D5: 46318 | E5: Não iniciada | F5: Proposta de reconstituição do TWG-PHC | G5: Lista de atores anteriores identificada; lacunas de representação identificadas; plano de atividades redigido; convites e pedido de autorização preparados | H5: 46304 | I5: Não iniciado | J5: Identificar que atores faltam convocar | K5: S3 | L5: AGJ | M5: 1 | N5: Atores anteriores identificados | O5: Backlog
A6: HIIP | B6: TWG-PHC | C6: Autoridades autorizam formalmente a reconstituição do grupo; sessão de refundação realizada com quórum; plano de atividades aceite pelos membros | D6: 46318 | E6: Não iniciada | F6: Proposta de reconstituição do TWG-PHC | G6: Lista de atores anteriores identificada; lacunas de representação identificadas; plano de atividades redigido; convites e pedido de autorização preparados | H6: 46304 | I6: Não iniciado | J6: Planear as atividades do grupo de trabalho | K6: S4 | L6: AGJ | M6: 3 | N6: Lista de atores | O6: Backlog
A7: HIIP | B7: TWG-PHC | C7: Autoridades autorizam formalmente a reconstituição do grupo; sessão de refundação realizada com quórum; plano de atividades aceite pelos membros | D7: 46318 | E7: Não iniciada | F7: Proposta de reconstituição do TWG-PHC | G7: Lista de atores anteriores identificada; lacunas de representação identificadas; plano de atividades redigido; convites e pedido de autorização preparados | H7: 46304 | I7: Não iniciado | J7: Preparar o pedido de autorização às autoridades | K7: S5 | L7: AGJ | M7: 1 | N7: Plano de atividades | O7: Backlog
A8: HIIP | B8: TWG-PHC | C8: Autoridades autorizam formalmente a reconstituição do grupo; sessão de refundação realizada com quórum; plano de atividades aceite pelos membros | D8: 46318 | E8: Não iniciada | J8: Obter autorização formal das autoridades | K8: S5 | L8: AGJ | M8: 2 | N8: Pedido de autorização; anuência da DNSP | O8: Backlog
A9: HIIP | B9: TWG-PHC | C9: Autoridades autorizam formalmente a reconstituição do grupo; sessão de refundação realizada com quórum; plano de atividades aceite pelos membros | D9: 46318 | E9: Não iniciada | J9: Convidar as autoridades e os membros | K9: S6 | L9: AGJ | M9: 1 | N9: Autorização formal | O9: Backlog
A10: HIIP | B10: TWG-PHC | C10: Autoridades autorizam formalmente a reconstituição do grupo; sessão de refundação realizada com quórum; plano de atividades aceite pelos membros | D10: 46318 | E10: Não iniciada | J10: Agendar o encontro com todos | K10: S6 | L10: AGJ | M10: 1 | N10: Convites enviados | O10: Backlog
A11: HIIP | B11: TWG-PHC | C11: Autoridades autorizam formalmente a reconstituição do grupo; sessão de refundação realizada com quórum; plano de atividades aceite pelos membros | D11: 46318 | E11: Não iniciada | J11: Conduzir a sessão de refundação do grupo | K11: S6 | L11: AGJ | M11: 1 | N11: Encontro agendado | O11: Backlog
A12: HIIP | B12: Background document - PHC | C12: Apresentado ao TWG-PHC; posição registada sobre o diagnóstico; ata com comentários e responsáveis; alterações incorporadas em versão datada | D12: 46332 | E12: Não iniciada | F12: Auditoria do trabalho anterior das consultoras | G12: Metodologia previamente aplicada identificada; inventário dos dados recolhidos e dos que faltam; registo do que foi prometido ao cliente, com prazos e produtos; lacunas listadas | H12: 46262 | I12: Feito | J12: Reuniões com as consultoras | K12: S1 | L12: AGJ | M12: 2 | O12: Done
A13: HIIP | B13: Background document - PHC | C13: Apresentado ao TWG-PHC; posição registada sobre o diagnóstico; ata com comentários e responsáveis; alterações incorporadas em versão datada | D13: 46332 | E13: Não iniciada | F13: Auditoria do trabalho anterior das consultoras | G13: Metodologia previamente aplicada identificada; inventário dos dados recolhidos e dos que faltam; registo do que foi prometido ao cliente, com prazos e produtos; lacunas listadas | H13: 46262 | I13: Feito | J13: Identificação da metodologia previamente aplicada | K13: S1 | L13: AGJ | M13: 2 | O13: Done
A14: HIIP | B14: Background document - PHC | C14: Apresentado ao TWG-PHC; posição registada sobre o diagnóstico; ata com comentários e responsáveis; alterações incorporadas em versão datada | D14: 46332 | E14: Não iniciada | F14: Auditoria do trabalho anterior das consultoras | G14: Metodologia previamente aplicada identificada; inventário dos dados recolhidos e dos que faltam; registo do que foi prometido ao cliente, com prazos e produtos; lacunas listadas | H14: 46262 | I14: Feito | J14: Inventário dos dados recolhidos e dos que faltam recolher | K14: S2 | L14: AGJ | M14: 2 | O14: Done
A15: HIIP | B15: Background document - PHC | C15: Apresentado ao TWG-PHC; posição registada sobre o diagnóstico; ata com comentários e responsáveis; alterações incorporadas em versão datada | D15: 46332 | E15: Não iniciada | F15: Auditoria do trabalho anterior das consultoras | G15: Metodologia previamente aplicada identificada; inventário dos dados recolhidos e dos que faltam; registo do que foi prometido ao cliente, com prazos e produtos; lacunas listadas | H15: 46262 | I15: Feito | J15: Levantamento do que foi prometido ao cliente, com prazos e produtos | K15: S2 | L15: AGJ | M15: 2 | O15: Done
A16: HIIP | B16: Background document - PHC | C16: Apresentado ao TWG-PHC; posição registada sobre o diagnóstico; ata com comentários e responsáveis; alterações incorporadas em versão datada | D16: 46332 | E16: Não iniciada | F16: Estrutura analítica | G16: Documento estruturado pelas alavancas do operational framework; guias de entrevista mapeados nas alavancas; material das consultoras mapeado; forma de apresentação de barreiras, lacunas, gargalos e fortalezas definida | H16: 46276 | I16: Não iniciado | J16: Estruturar o documento pelas alavancas do operational framework | K16: S3 | L16: AGJ | M16: 2 | N16: Auditoria | O16: Backlog
A17: HIIP | B17: Background document - PHC | C17: Apresentado ao TWG-PHC; posição registada sobre o diagnóstico; ata com comentários e responsáveis; alterações incorporadas em versão datada | D17: 46332 | E17: Não iniciada | F17: Estrutura analítica | G17: Documento estruturado pelas alavancas do operational framework; guias de entrevista mapeados nas alavancas; material das consultoras mapeado; forma de apresentação de barreiras, lacunas, gargalos e fortalezas definida | H17: 46276 | I17: Não iniciado | J17: Reescrever os guias de entrevista mapeados nas alavancas | K17: S3 | L17: AGJ | M17: 3 | N17: Estrutura analítica | O17: Backlog
A18: HIIP | B18: Background document - PHC | C18: Apresentado ao TWG-PHC; posição registada sobre o diagnóstico; ata com comentários e responsáveis; alterações incorporadas em versão datada | D18: 46332 | E18: Não iniciada | F18: Estrutura analítica | G18: Documento estruturado pelas alavancas do operational framework; guias de entrevista mapeados nas alavancas; material das consultoras mapeado; forma de apresentação de barreiras, lacunas, gargalos e fortalezas definida | H18: 46276 | I18: Não iniciado | J18: Mapear o material das consultoras contra as alavancas | K18: S3 | L18: AGJ | M18: 2 | N18: Estrutura analítica | O18: Backlog
A19: HIIP | B19: Background document - PHC | C19: Apresentado ao TWG-PHC; posição registada sobre o diagnóstico; ata com comentários e responsáveis; alterações incorporadas em versão datada | D19: 46332 | E19: Não iniciada | F19: Estrutura analítica | G19: Documento estruturado pelas alavancas do operational framework; guias de entrevista mapeados nas alavancas; material das consultoras mapeado; forma de apresentação de barreiras, lacunas, gargalos e fortalezas definida | H19: 46276 | I19: Não iniciado | J19: Definir a forma de apresentação de barreiras, lacunas, gargalos e fortalezas | K19: S3 | L19: AGJ | M19: 1 | O19: Backlog
A20: HIIP | B20: Background document - PHC | C20: Apresentado ao TWG-PHC; posição registada sobre o diagnóstico; ata com comentários e responsáveis; alterações incorporadas em versão datada | D20: 46332 | E20: Não iniciada | F20: Espinha dorsal quantitativa | G20: Indicadores extraídos com data de extração; qualidade e completude avaliadas; anomalias listadas para interrogar no campo | H20: 46276 | I20: Não iniciado | J20: Extrair os indicadores do DHIS2 | K20: S3 | L20: AGJ | M20: 3 | O20: Backlog
A21: HIIP | B21: Background document - PHC | C21: Apresentado ao TWG-PHC; posição registada sobre o diagnóstico; ata com comentários e responsáveis; alterações incorporadas em versão datada | D21: 46332 | E21: Não iniciada | F21: Espinha dorsal quantitativa | G21: Indicadores extraídos com data de extração; qualidade e completude avaliadas; anomalias listadas para interrogar no campo | H21: 46276 | I21: Não iniciado | J21: Avaliar a qualidade e a completude dos dados extraídos | K21: S3 | L21: AGJ | M21: 2 | N21: Extração do DHIS2 | O21: Backlog
A22: HIIP | B22: Background document - PHC | C22: Apresentado ao TWG-PHC; posição registada sobre o diagnóstico; ata com comentários e responsáveis; alterações incorporadas em versão datada | D22: 46332 | E22: Não iniciada | F22: Espinha dorsal quantitativa | G22: Indicadores extraídos com data de extração; qualidade e completude avaliadas; anomalias listadas para interrogar no campo | H22: 46276 | I22: Não iniciado | J22: Identificar anomalias a interrogar no campo | K22: S3 | L22: AGJ | M22: 1 | N22: Avaliação de qualidade | O22: Backlog
A23: HIIP | B23: Background document - PHC | C23: Apresentado ao TWG-PHC; posição registada sobre o diagnóstico; ata com comentários e responsáveis; alterações incorporadas em versão datada | D23: 46332 | E23: Não iniciada | F23: Preparação das visitas piloto | G23: Anuência da DNSP registada; itens do HHFA selecionados com justificação; questionários testados no dispositivo antes da partida; lista de unidades e informantes acordada | H23: 46276 | I23: Não iniciado | J23: Pedir anuência à DNSP para as visitas e entrevistas piloto | K23: S3 | L23: AGJ | M23: 2 | O23: Backlog
A24: HIIP | B24: Background document - PHC | C24: Apresentado ao TWG-PHC; posição registada sobre o diagnóstico; ata com comentários e responsáveis; alterações incorporadas em versão datada | D24: 46332 | E24: Não iniciada | F24: Preparação das visitas piloto | G24: Anuência da DNSP registada; itens do HHFA selecionados com justificação; questionários testados no dispositivo antes da partida; lista de unidades e informantes acordada | H24: 46276 | I24: Não iniciado | J24: Selecionar do HHFA o que capturar neste piloto | K24: S3 | L24: AGJ | M24: 2 | O24: Backlog
A25: HIIP | B25: Background document - PHC | C25: Apresentado ao TWG-PHC; posição registada sobre o diagnóstico; ata com comentários e responsáveis; alterações incorporadas em versão datada | D25: 46332 | E25: Não iniciada | F25: Preparação das visitas piloto | G25: Anuência da DNSP registada; itens do HHFA selecionados com justificação; questionários testados no dispositivo antes da partida; lista de unidades e informantes acordada | H25: 46276 | I25: Não iniciado | J25: Preparar os questionários a partir do HHFA | K25: S3 | L25: AGJ | M25: 3 | N25: Seleção de itens do HHFA | O25: Backlog
A26: HIIP | B26: Background document - PHC | C26: Apresentado ao TWG-PHC; posição registada sobre o diagnóstico; ata com comentários e responsáveis; alterações incorporadas em versão datada | D26: 46332 | E26: Não iniciada | F26: Preparação das visitas piloto | G26: Anuência da DNSP registada; itens do HHFA selecionados com justificação; questionários testados no dispositivo antes da partida; lista de unidades e informantes acordada | H26: 46276 | I26: Não iniciado | J26: Carregar os questionários no KoboToolbox | K26: S3 | L26: AGJ | M26: 1 | N26: Questionários preparados | O26: Backlog
A27: HIIP | B27: Background document - PHC | C27: Apresentado ao TWG-PHC; posição registada sobre o diagnóstico; ata com comentários e responsáveis; alterações incorporadas em versão datada | D27: 46332 | E27: Não iniciada | F27: Preparação das visitas piloto | G27: Anuência da DNSP registada; itens do HHFA selecionados com justificação; questionários testados no dispositivo antes da partida; lista de unidades e informantes acordada | H27: 46276 | I27: Não iniciado | J27: Definir unidades, datas e perfis de informantes | K27: S3 | L27: AGJ | M27: 2 | N27: Anuência da DNSP | O27: Backlog
A28: HIIP | B28: Background document - PHC | C28: Apresentado ao TWG-PHC; posição registada sobre o diagnóstico; ata com comentários e responsáveis; alterações incorporadas em versão datada | D28: 46332 | E28: Não iniciada | F28: Visitas piloto realizadas | G28: Unidades previstas visitadas; dados sincronizados do Kobo; notas de entrevista transcritas; limitações do instrumento anotadas | H28: 46290 | I28: Não iniciado | J28: Conduzir as visitas às unidades sanitárias | K28: S4 | L28: AGJ | M28: 6 | N28: Preparação das visitas piloto | O28: Backlog
A29: HIIP | B29: Background document - PHC | C29: Apresentado ao TWG-PHC; posição registada sobre o diagnóstico; ata com comentários e responsáveis; alterações incorporadas em versão datada | D29: 46332 | E29: Não iniciada | F29: Visitas piloto realizadas | G29: Unidades previstas visitadas; dados sincronizados do Kobo; notas de entrevista transcritas; limitações do instrumento anotadas | H29: 46290 | I29: Não iniciado | J29: Conduzir entrevistas com profissionais e gestores locais, provinciais e nacionais | K29: S4 | L29: AGJ | M29: 4 | N29: Preparação das visitas piloto | O29: Backlog
A30: HIIP | B30: Background document - PHC | C30: Apresentado ao TWG-PHC; posição registada sobre o diagnóstico; ata com comentários e responsáveis; alterações incorporadas em versão datada | D30: 46332 | E30: Não iniciada | F30: Visitas piloto realizadas | G30: Unidades previstas visitadas; dados sincronizados do Kobo; notas de entrevista transcritas; limitações do instrumento anotadas | H30: 46290 | I30: Não iniciado | J30: Registar e organizar o material recolhido | K30: S4 | L30: AGJ | M30: 2 | N30: Visitas realizadas | O30: Backlog
A31: HIIP | B31: Background document - PHC | C31: Apresentado ao TWG-PHC; posição registada sobre o diagnóstico; ata com comentários e responsáveis; alterações incorporadas em versão datada | D31: 46332 | E31: Não iniciada | F31: Visitas piloto realizadas | G31: Unidades previstas visitadas; dados sincronizados do Kobo; notas de entrevista transcritas; limitações do instrumento anotadas | H31: 46290 | I31: Não iniciado | J31: Registar as lições do piloto para o desenho do HHFA | K31: S4 | L31: AGJ | M31: 1 | N31: Visitas realizadas | O31: Backlog
A32: HIIP | B32: Background document - PHC | C32: Apresentado ao TWG-PHC; posição registada sobre o diagnóstico; ata com comentários e responsáveis; alterações incorporadas em versão datada | D32: 46332 | E32: Não iniciada | F32: Síntese e mapeamento | G32: Achados codificados; barreiras, lacunas, gargalos e fortalezas classificados por estrutura, processo e resultado e mapeados nas alavancas; modelo de cuidados atual descrito; evidências dos informantes contrapostas à evidência científica atual | H32: 46304 | I32: Não iniciado | J32: Codificar e sintetizar os achados qualitativos | K32: S5 | L32: AGJ | M32: 4 | N32: Visitas piloto realizadas | O32: Backlog
A33: HIIP | B33: Background document - PHC | C33: Apresentado ao TWG-PHC; posição registada sobre o diagnóstico; ata com comentários e responsáveis; alterações incorporadas em versão datada | D33: 46332 | E33: Não iniciada | F33: Síntese e mapeamento | G33: Achados codificados; barreiras, lacunas, gargalos e fortalezas classificados por estrutura, processo e resultado e mapeados nas alavancas; modelo de cuidados atual descrito; evidências dos informantes contrapostas à evidência científica atual | H33: 46304 | I33: Não iniciado | J33: Mapear barreiras, lacunas, gargalos e fortalezas por estrutura, processo e resultado | K33: S5 | L33: AGJ | M33: 3 | N33: Síntese qualitativa | O33: Backlog
A34: HIIP | B34: Background document - PHC | C34: Apresentado ao TWG-PHC; posição registada sobre o diagnóstico; ata com comentários e responsáveis; alterações incorporadas em versão datada | D34: 46332 | E34: Não iniciada | F34: Síntese e mapeamento | G34: Achados codificados; barreiras, lacunas, gargalos e fortalezas classificados por estrutura, processo e resultado e mapeados nas alavancas; modelo de cuidados atual descrito; evidências dos informantes contrapostas à evidência científica atual | H34: 46304 | I34: Não iniciado | J34: Descrever o modelo de cuidados atual | K34: S5 | L34: AGJ | M34: 3 | N34: Síntese qualitativa | O34: Backlog
A35: HIIP | B35: Background document - PHC | C35: Apresentado ao TWG-PHC; posição registada sobre o diagnóstico; ata com comentários e responsáveis; alterações incorporadas em versão datada | D35: 46332 | E35: Não iniciada | F35: Síntese e mapeamento | G35: Achados codificados; barreiras, lacunas, gargalos e fortalezas classificados por estrutura, processo e resultado e mapeados nas alavancas; modelo de cuidados atual descrito; evidências dos informantes contrapostas à evidência científica atual | H35: 46304 | I35: Não iniciado | J35: Contrapor as evidências dos informantes à evidência científica atual | K35: S5 | L35: AGJ | M35: 3 | N35: Mapeamento | O35: Backlog
A36: HIIP | B36: Background document - PHC | C36: Apresentado ao TWG-PHC; posição registada sobre o diagnóstico; ata com comentários e responsáveis; alterações incorporadas em versão datada | D36: 46332 | E36: Não iniciada | F36: Background document v1 | G36: Forma de apresentação aplicada; secção de contraste escrita; linguagem adequada ao cliente; evidências e referências revistas; revisão do country office resolvida | H36: 46318 | I36: Não iniciado | J36: Redigir a secção de contraste entre o que se acredita e o que se observou | K36: S5 | L36: AGJ | M36: 2 | N36: Síntese e mapeamento | O36: Backlog
... A40: HIIP | B40: Background document - PHC | C40: Apresentado ao TWG-PHC; posição registada sobre o diagnóstico; ata com comentários e responsáveis; alterações incorporadas em versão datada | D40: 46332 | E40: Não iniciada | F40: Background document v1 | G40: Forma de apresentação aplicada; secção de contraste escrita; linguagem adequada ao cliente; evidências e referências revistas; revisão do country office resolvida | H40: 46318 | I40: Não iniciado | J40: Revisão do country office | K40: S6 | L40: AGJ | M40: 2 | N40: Background document v1 | O40: Backlog
A41: HIIP | B41: Background document - PHC | C41: Apresentado ao TWG-PHC; posição registada sobre o diagnóstico; ata com comentários e responsáveis; alterações incorporadas em versão datada | D41: 46332 | E41: Não iniciada | J41: Apresentar o documento ao TWG-PHC para validação | K41: S6 | L41: AGJ | M41: 1 | N41: TWG-PHC refundado; Background v1 | O41: Backlog
A42: HIIP | B42: Background document - PHC | C42: Apresentado ao TWG-PHC; posição registada sobre o diagnóstico; ata com comentários e responsáveis; alterações incorporadas em versão datada | D42: 46332 | E42: Não iniciada | J42: Incorporar os comentários do TWG-PHC | K42: S7 | L42: AGJ | M42: 2 | N42: Sessão de validação | O42: Backlog
A43: HIIP | B43: Strategy document - PHC | C43: Apresentada ao TWG-PHC; posição registada sobre cada área priorizada (aceite/alterada/rejeitada); ata com decisões e responsáveis; MINSA confirma que serve de documento de política habilitante; alterações acordadas incorporadas em versão datada | D43: 46346 | E43: Não iniciada | F43: Mapa de barreiras, lacunas, gargalos e fortalezas | G43: Itens classificados por estrutura, processo e resultado e mapeados nas alavancas do framework; cada item com fonte identificada; intervenções candidatas com referência e nível de evidência | H43: 46304 | I43: Não iniciado | J43: Mapear barreiras, lacunas, gargalos e fortalezas por estrutura, processo e resultado | K43: S5 | L43: AGJ | M43: 4 | N43: Síntese qualitativa do campo | O43: Backlog
A44: HIIP | B44: Strategy document - PHC | C44: Apresentada ao TWG-PHC; posição registada sobre cada área priorizada (aceite/alterada/rejeitada); ata com decisões e responsáveis; MINSA confirma que serve de documento de política habilitante; alterações acordadas incorporadas em versão datada | D44: 46346 | E44: Não iniciada | F44: Mapa de barreiras, lacunas, gargalos e fortalezas | G44: Itens classificados por estrutura, processo e resultado e mapeados nas alavancas do framework; cada item com fonte identificada; intervenções candidatas com referência e nível de evidência | H44: 46304 | I44: Não iniciado | J44: Rever evidência de intervenções para cada barreira, lacuna e gargalo | K44: S5 | L44: AGJ | M44: 5 | N44: Mapa de barreiras | O44: Backlog
...

Sheet 3. Tarefas
A1: Backlog de tarefas, ordenado por sprint
A3: Sprint | B3: Frente | C3: Resultado | D3: Tarefa | E3: Responsável | F3: Estimativa (dias) | G3: Depende de | H3: Estado | I3: Aprendizado
A4: S1 | B4: Background document - PHC | C4: Auditoria do trabalho anterior das consultoras | D4: Reuniões com as consultoras | E4: AGJ | F4: 2 | H4: Done
A5: S1 | B5: Background document - PHC | C5: Auditoria do trabalho anterior das consultoras | D5: Identificação da metodologia previamente aplicada | E5: AGJ | F5: 2 | H5: Done
A6: S1 | B6: PFM | C6: TWG-PFM constituído | D6: Finalizar o ToR do TWG-PFM | E6: AGJ | F6: 2 | H6: Done
A7: S2 | B7: Background document - PHC | C7: Auditoria do trabalho anterior das consultoras | D7: Inventário dos dados recolhidos e dos que faltam recolher | E7: AGJ | F7: 2 | H7: Done
A8: S2 | B8: Background document - PHC | C8: Auditoria do trabalho anterior das consultoras | D8: Levantamento do que foi prometido ao cliente, com prazos e produtos | E8: AGJ | F8: 2 | H8: Done
A9: S2 | B9: PFM | C9: TWG-PFM constituído | D9: Confirmar a lista de participantes | E9: AGJ | F9: 2 | G9: ToR | H9: Done
A10: S3 | B10: Background document - PHC | C10: Estrutura analítica | D10: Estruturar o documento pelas alavancas do operational framework | E10: AGJ | F10: 2 | G10: Auditoria | H10: Backlog
A11: S3 | B11: Background document - PHC | C11: Estrutura analítica | D11: Reescrever os guias de entrevista mapeados nas alavancas | E11: AGJ | F11: 3 | G11: Estrutura analítica | H11: Backlog
A12: S3 | B12: Background document - PHC | C12: Estrutura analítica | D12: Mapear o material das consultoras contra as alavancas | E12: AGJ | F12: 2 | G12: Estrutura analítica | H12: Backlog
A13: S3 | B13: Background document - PHC | C13: Estrutura analítica | D13: Definir a forma de apresentação de barreiras, lacunas, gargalos e fortalezas | E13: AGJ | F13: 1 | H13: Backlog
A14: S3 | B14: Background document - PHC | C14: Espinha dorsal quantitativa | D14: Extrair os indicadores do DHIS2 | E14: AGJ | F14: 3 | H14: Backlog
A15: S3 | B15: Background document - PHC | C15: Espinha dorsal quantitativa | D15: Avaliar a qualidade e a completude dos dados extraídos | E15: AGJ | F15: 2 | G15: Extração do DHIS2 | H15: Backlog
A16: S3 | B16: Background document - PHC | C16: Espinha dorsal quantitativa | D16: Identificar anomalias a interrogar no campo | E16: AGJ | F16: 1 | G16: Avaliação de qualidade | H16: Backlog
A17: S3 | B17: Background document - PHC | C17: Preparação das visitas piloto | D17: Pedir anuência à DNSP para as visitas e entrevistas piloto | E17: AGJ | F17: 2 | H17: Backlog
A18: S3 | B18: Background document - PHC | C18: Preparação das visitas piloto | D18: Selecionar do HHFA o que capturar neste piloto | E18: AGJ | F18: 2 | H18: Backlog
A19: S3 | B19: Background document - PHC | C19: Preparação das visitas piloto | D19: Preparar os questionários a partir do HHFA | E19: AGJ | F19: 3 | G19: Seleção de itens do HHFA | H19: Backlog
A20: S3 | B20: Background document - PHC | C20: Preparação das visitas piloto | D20: Carregar os questionários no KoboToolbox | E20: AGJ | F20: 1 | G20: Questionários preparados | H20: Backlog
A21: S3 | B21: Background document - PHC | C21: Preparação das visitas piloto | D21: Definir unidades, datas e perfis de informantes | E21: AGJ | F21: 2 | G21: Anuência da DNSP | H21: Backlog
A22: S3 | B22: HHFA e diagnóstico situacional | C22: Acordo interagências | D22: Manter as reuniões de alinhamento com o UNICEF e o UNFPA | E22: AGJ | F22: 2 | H22: In progress
A23: S3 | B23: HHFA e diagnóstico situacional | C23: Adesão ao inquérito já contratado | D23: Obter e rever a amostragem, o ToR e o contrato já decididos | E23: AGJ | F23: 1 | H23: Backlog
A24: S3 | B24: HHFA e diagnóstico situacional | C24: Adesão ao inquérito já contratado | D24: Avaliar se a amostra serve às perguntas do diagnóstico dos CSP | E24: AGJ | F24: 2 | G24: Amostragem obtida | H24: Backlog
A25: S3 | B25: HHFA e diagnóstico situacional | C25: Adesão ao inquérito já contratado | D25: Identificar que margem existe para acrescentar itens ao instrumento | E25: AGJ | F25: 1 | G25: Avaliação da amostra | H25: Backlog
A26: S3 | B26: HHFA e diagnóstico situacional | C26: Adesão ao inquérito já contratado | D26: Participar na reunião de arranque com a empresa contratada | E26: AGJ | F26: 1 | H26: Backlog
A27: S3 | B27: HHFA e diagnóstico situacional | C27: Adesão ao inquérito já contratado | D27: Alinhar o cronograma de recolha com o calendário do HIIP | E27: AGJ | F27: 1 | G27: Reunião de arranque | H27: Backlog
A28: S3 | B28: HHFA e diagnóstico situacional | C28: Seleção de itens | D28: Selecionar do HHFA os itens a capturar no piloto | E28: AGJ | F28: 2 | G28: Margem de inclusão confirmada | H28: Backlog
A29: S3 | B29: PFM | C29: TWG-PFM constituído | D29: Organizar o cronograma e enviar os convites | E29: AGJ | F29: 2 | G29: Lista de participantes | H29: In progress
A30: S3 | B30: PFM | C30: TWG-PFM constituído | D30: Conduzir as entrevistas preparatórias com os membros | E30: AGJ | F30: 4 | G30: Convites | H30: Backlog
A31: S3 | B31: PFM | C31: Consultoria PFM contratada | D31: Reunião com o Banco Mundial sobre o financiamento do especialista local | E31: AGJ | F31: 1 | H31: Backlog
A32: S3 | B32: Relatórios contratuais do HIIP | C32: Calendário de reporte | D32: Confirmar o calendário contratual de reporte | E32: AGJ | F32: 1 | H32: Backlog
A33: S3 | B33: TWG-PHC | C33: Proposta de reconstituição do TWG-PHC | D33: Identificar os atores anteriormente convocados | E33: AGJ | F33: 2 | H33: Backlog
A34: S3 | B34: TWG-PHC | C34: Proposta de reconstituição do TWG-PHC | D34: Identificar que atores faltam convocar | E34: AGJ | F34: 1 | G34: Atores anteriores identificados | H34: Backlog
A35: S4 | B35: Background document - PHC | C35: Visitas piloto realizadas | D35: Conduzir as visitas às unidades sanitárias | E35: AGJ | F35: 6 | G35: Preparação das visitas piloto | H35: Backlog
A36: S4 | B36: Background document - PHC | C36: Visitas piloto realizadas | D36: Conduzir entrevistas com profissionais e gestores locais, provinciais e nacionais | E36: AGJ | F36: 4 | G36: Preparação das visitas piloto | H36: Backlog
A37: S4 | B37: Background document - PHC | C37: Visitas piloto realizadas | D37: Registar e organizar o material recolhido | E37: AGJ | F37: 2 | G37: Visitas realizadas | H37: Backlog
A38: S4 | B38: Background document - PHC | C38: Visitas piloto realizadas | D38: Registar as lições do piloto para o desenho do HHFA | E38: AGJ | F38: 1 | G38: Visitas realizadas | H38: Backlog
A39: S4 | B39: HHFA e diagnóstico situacional | C39: Acordo interagências | D39: Definir o âmbito partilhado e a divisão de custos | E39: AGJ | F39: 2 | G39: Reuniões de alinhamento | H39: Backlog
A40: S4 | B40: PFM | C40: TWG-PFM constituído | D40: Produzir o relatório das entrevistas preparatórias | E40: AGJ | F40: 3 | G40: Entrevistas preparatórias | H40: Backlog
A41: S4 | B41: PFM | C41: TWG-PFM constituído | D41: Conduzir a sessão inaugural | E41: AGJ | F41: 1 | G41: Relatório das entrevistas | H41: Backlog
...

Sheet 4. Sprints
A1: Calendário de sprints - quinzenal, 3 de agosto de 2026 a 2 de julho de 2027
A3: Sprint | B3: Início | C3: Fim | D3: Tarefas previstas | E3: Dias previstos
A4: S1 | B4: 46237 | C4: 46248 | D4: =COUNTIF('3. Tarefas'!$A$4:$A$162,$A4) -> 3 | E4: =SUMIF('3. Tarefas'!$A$4:$A$162,$A4,'3. Tarefas'!$F$4:$F$162) -> 6
A5: S2 | B5: 46251 | C5: 46262 | D5: =COUNTIF('3. Tarefas'!$A$4:$A$162,$A5) -> 3 | E5: =SUMIF('3. Tarefas'!$A$4:$A$162,$A5,'3. Tarefas'!$F$4:$F$162) -> 6
A6: S3 | B6: 46265 | C6: 46276 | D6: =COUNTIF('3. Tarefas'!$A$4:$A$162,$A6) -> 25 | E6: =SUMIF('3. Tarefas'!$A$4:$A$162,$A6,'3. Tarefas'!$F$4:$F$162) -> 45
A7: S4 | B7: 46279 | C7: 46290 | D7: =COUNTIF('3. Tarefas'!$A$4:$A$162,$A7) -> 11 | E7: =SUMIF('3. Tarefas'!$A$4:$A$162,$A7,'3. Tarefas'!$F$4:$F$162) -> 28
A8: S5 | B8: 46293 | C8: 46304 | D8: =COUNTIF('3. Tarefas'!$A$4:$A$162,$A8) -> 20 | E8: =SUMIF('3. Tarefas'!$A$4:$A$162,$A8,'3. Tarefas'!$F$4:$F$162) -> 62
A9: S6 | B9: 46307 | C9: 46318 | D9: =COUNTIF('3. Tarefas'!$A$4:$A$162,$A9) -> 24 | E9: =SUMIF('3. Tarefas'!$A$4:$A$162,$A9,'3. Tarefas'!$F$4:$F$162) -> 53
A10: S7 | B10: 46321 | C10: 46332 | D10: =COUNTIF('3. Tarefas'!$A$4:$A$162,$A10) -> 8 | E10: =SUMIF('3. Tarefas'!$A$4:$A$162,$A10,'3. Tarefas'!$F$4:$F$162) -> 17
A11: S8 | B11: 46335 | C11: 46346 | D11: =COUNTIF('3. Tarefas'!$A$4:$A$162,$A11) -> 12 | E11: =SUMIF('3. Tarefas'!$A$4:$A$162,$A11,'3. Tarefas'!$F$4:$F$162) -> 34
A12: S9 | B12: 46349 | C12: 46360 | D12: =COUNTIF('3. Tarefas'!$A$4:$A$162,$A12) -> 9 | E12: =SUMIF('3. Tarefas'!$A$4:$A$162,$A12,'3. Tarefas'!$F$4:$F$162) -> 27
A13: S10 | B13: 46363 | C13: 46374 | D13: =COUNTIF('3. Tarefas'!$A$4:$A$162,$A13) -> 6 | E13: =SUMIF('3. Tarefas'!$A$4:$A$162,$A13,'3. Tarefas'!$F$4:$F$162) -> 23
A14: S11 | B14: 46391 | C14: 46402 | D14: =COUNTIF('3. Tarefas'!$A$4:$A$162,$A14) -> 3 | E14: =SUMIF('3. Tarefas'!$A$4:$A$162,$A14,'3. Tarefas'!$F$4:$F$162) -> 12
A15: S12 | B15: 46405 | C15: 46416 | D15: =COUNTIF('3. Tarefas'!$A$4:$A$162,$A15) -> 3 | E15: =SUMIF('3. Tarefas'!$A$4:$A$162,$A15,'3. Tarefas'!$F$4:$F$162) -> 13
... A26: S23 | B26: 46559 | C26: 46570 | D26: =COUNTIF('3. Tarefas'!$A$4:$A$162,$A26) -> 0 | E26: =SUMIF('3. Tarefas'!$A$4:$A$162,$A26,'3. Tarefas'!$F$4:$F$162) -> 0
A27: Recorrente | D27: =COUNTIF('3. Tarefas'!$A$4:$A$162,"Recorrente") -> 4 | E27: =SUMIF('3. Tarefas'!$A$4:$A$162,"Recorrente",'3. Tarefas'!$F$4:$F$162) -> 6
A28: TBC | D28: =COUNTIF('3. Tarefas'!$A$4:$A$162,"TBC") -> 4 | E28: =SUMIF('3. Tarefas'!$A$4:$A$162,"TBC",'3. Tarefas'!$F$4:$F$162) -> 16

Sheet 1. TWG-PHC
A1: TWG-PHC
A3: Projeto | B3: Frente de trabalho (produto) | C3: Validação externa | D3: Data validação | E3: Estado validação | F3: Resultado (output) | G3: Definição de feito (resultado) | H3: Data resultado | I3: Estado resultado | J3: Tarefa | K3: Sprint | L3: Responsável | M3: Estimativa (dias) | N3: Depende de | O3: Estado tarefa | P3: Aprendizado
A4: HIIP | B4: TWG-PHC | C4: Autoridades autorizam formalmente a reconstituição do grupo; sessão de refundação realizada com quórum; plano de atividades aceite pelos membros | D4: 46318 | E4: Não iniciada | F4: Proposta de reconstituição do TWG-PHC | G4: Lista de atores anteriores identificada; lacunas de representação identificadas; plano de atividades redigido; convites e pedido de autorização preparados | H4: 46304 | I4: Não iniciado | J4: Identificar os atores anteriormente convocados | K4: S3 | L4: AGJ | M4: 2 | O4: Backlog
A5: HIIP | B5: TWG-PHC | C5: Autoridades autorizam formalmente a reconstituição do grupo; sessão de refundação realizada com quórum; plano de atividades aceite pelos membros | D5: 46318 | E5: Não iniciada | F5: Proposta de reconstituição do TWG-PHC | G5: Lista de atores anteriores identificada; lacunas de representação identificadas; plano de atividades redigido; convites e pedido de autorização preparados | H5: 46304 | I5: Não iniciado | J5: Identificar que atores faltam convocar | K5: S3 | L5: AGJ | M5: 1 | N5: Atores anteriores identificados | O5: Backlog
A6: HIIP | B6: TWG-PHC | C6: Autoridades autorizam formalmente a reconstituição do grupo; sessão de refundação realizada com quórum; plano de atividades aceite pelos membros | D6: 46318 | E6: Não iniciada | F6: Proposta de reconstituição do TWG-PHC | G6: Lista de atores anteriores identificada; lacunas de representação identificadas; plano de atividades redigido; convites e pedido de autorização preparados | H6: 46304 | I6: Não iniciado | J6: Planear as atividades do grupo de trabalho | K6: S4 | L6: AGJ | M6: 3 | N6: Lista de atores | O6: Backlog
A7: HIIP | B7: TWG-PHC | C7: Autoridades autorizam formalmente a reconstituição do grupo; sessão de refundação realizada com quórum; plano de atividades aceite pelos membros | D7: 46318 | E7: Não iniciada | F7: Proposta de reconstituição do TWG-PHC | G7: Lista de atores anteriores identificada; lacunas de representação identificadas; plano de atividades redigido; convites e pedido de autorização preparados | H7: 46304 | I7: Não iniciado | J7: Preparar o pedido de autorização às autoridades | K7: S5 | L7: AGJ | M7: 1 | N7: Plano de atividades | O7: Backlog
A8: HIIP | B8: TWG-PHC | C8: Autoridades autorizam formalmente a reconstituição do grupo; sessão de refundação realizada com quórum; plano de atividades aceite pelos membros | D8: 46318 | E8: Não iniciada | J8: Obter autorização formal das autoridades | K8: S5 | L8: AGJ | M8: 2 | N8: Pedido de autorização; anuência da DNSP | O8: Backlog
A9: HIIP | B9: TWG-PHC | C9: Autoridades autorizam formalmente a reconstituição do grupo; sessão de refundação realizada com quórum; plano de atividades aceite pelos membros | D9: 46318 | E9: Não iniciada | J9: Convidar as autoridades e os membros | K9: S6 | L9: AGJ | M9: 1 | N9: Autorização formal | O9: Backlog
A10: HIIP | B10: TWG-PHC | C10: Autoridades autorizam formalmente a reconstituição do grupo; sessão de refundação realizada com quórum; plano de atividades aceite pelos membros | D10: 46318 | E10: Não iniciada | J10: Agendar o encontro com todos | K10: S6 | L10: AGJ | M10: 1 | N10: Convites enviados | O10: Backlog
A11: HIIP | B11: TWG-PHC | C11: Autoridades autorizam formalmente a reconstituição do grupo; sessão de refundação realizada com quórum; plano de atividades aceite pelos membros | D11: 46318 | E11: Não iniciada | J11: Conduzir a sessão de refundação do grupo | K11: S6 | L11: AGJ | M11: 1 | N11: Encontro agendado | O11: Backlog

Sheet 2. Background document
A1: Background document - PHC
A3: Projeto | B3: Frente de trabalho (produto) | C3: Validação externa | D3: Data validação | E3: Estado validação | F3: Resultado (output) | G3: Definição de feito (resultado) | H3: Data resultado | I3: Estado resultado | J3: Tarefa | K3: Sprint | L3: Responsável | M3: Estimativa (dias) | N3: Depende de | O3: Estado tarefa | P3: Aprendizado
A4: HIIP | B4: Background document - PHC | C4: Apresentado ao TWG-PHC; posição registada sobre o diagnóstico; ata com comentários e responsáveis; alterações incorporadas em versão datada | D4: 46332 | E4: Não iniciada | F4: Auditoria do trabalho anterior das consultoras | G4: Metodologia previamente aplicada identificada; inventário dos dados recolhidos e dos que faltam; registo do que foi prometido ao cliente, com prazos e produtos; lacunas listadas | H4: 46262 | I4: Feito | J4: Reuniões com as consultoras | K4: S1 | L4: AGJ | M4: 2 | O4: Done
A5: HIIP | B5: Background document - PHC | C5: Apresentado ao TWG-PHC; posição registada sobre o diagnóstico; ata com comentários e responsáveis; alterações incorporadas em versão datada | D5: 46332 | E5: Não iniciada | F5: Auditoria do trabalho anterior das consultoras | G5: Metodologia previamente aplicada identificada; inventário dos dados recolhidos e dos que faltam; registo do que foi prometido ao cliente, com prazos e produtos; lacunas listadas | H5: 46262 | I5: Feito | J5: Identificação da metodologia previamente aplicada | K5: S1 | L5: AGJ | M5: 2 | O5: Done
A6: HIIP | B6: Background document - PHC | C6: Apresentado ao TWG-PHC; posição registada sobre o diagnóstico; ata com comentários e responsáveis; alterações incorporadas em versão datada | D6: 46332 | E6: Não iniciada | F6: Auditoria do trabalho anterior das consultoras | G6: Metodologia previamente aplicada identificada; inventário dos dados recolhidos e dos que faltam; registo do que foi prometido ao cliente, com prazos e produtos; lacunas listadas | H6: 46262 | I6: Feito | J6: Inventário dos dados recolhidos e dos que faltam recolher | K6: S2 | L6: AGJ | M6: 2 | O6: Done
A7: HIIP | B7: Background document - PHC | C7: Apresentado ao TWG-PHC; posição registada sobre o diagnóstico; ata com comentários e responsáveis; alterações incorporadas em versão datada | D7: 46332 | E7: Não iniciada | F7: Auditoria do trabalho anterior das consultoras | G7: Metodologia previamente aplicada identificada; inventário dos dados recolhidos e dos que faltam; registo do que foi prometido ao cliente, com prazos e produtos; lacunas listadas | H7: 46262 | I7: Feito | J7: Levantamento do que foi prometido ao cliente, com prazos e produtos | K7: S2 | L7: AGJ | M7: 2 | O7: Done
A8: HIIP | B8: Background document - PHC | C8: Apresentado ao TWG-PHC; posição registada sobre o diagnóstico; ata com comentários e responsáveis; alterações incorporadas em versão datada | D8: 46332 | E8: Não iniciada | F8: Estrutura analítica | G8: Documento estruturado pelas alavancas do operational framework; guias de entrevista mapeados nas alavancas; material das consultoras mapeado; forma de apresentação de barreiras, lacunas, gargalos e fortalezas definida | H8: 46276 | I8: Não iniciado | J8: Estruturar o documento pelas alavancas do operational framework | K8: S3 | L8: AGJ | M8: 2 | N8: Auditoria | O8: Backlog
A9: HIIP | B9: Background document - PHC | C9: Apresentado ao TWG-PHC; posição registada sobre o diagnóstico; ata com comentários e responsáveis; alterações incorporadas em versão datada | D9: 46332 | E9: Não iniciada | F9: Estrutura analítica | G9: Documento estruturado pelas alavancas do operational framework; guias de entrevista mapeados nas alavancas; material das consultoras mapeado; forma de apresentação de barreiras, lacunas, gargalos e fortalezas definida | H9: 46276 | I9: Não iniciado | J9: Reescrever os guias de entrevista mapeados nas alavancas | K9: S3 | L9: AGJ | M9: 3 | N9: Estrutura analítica | O9: Backlog
A10: HIIP | B10: Background document - PHC | C10: Apresentado ao TWG-PHC; posição registada sobre o diagnóstico; ata com comentários e responsáveis; alterações incorporadas em versão datada | D10: 46332 | E10: Não iniciada | F10: Estrutura analítica | G10: Documento estruturado pelas alavancas do operational framework; guias de entrevista mapeados nas alavancas; material das consultoras mapeado; forma de apresentação de barreiras, lacunas, gargalos e fortalezas definida | H10: 46276 | I10: Não iniciado | J10: Mapear o material das consultoras contra as alavancas | K10: S3 | L10: AGJ | M10: 2 | N10: Estrutura analítica | O10: Backlog
A11: HIIP | B11: Background document - PHC | C11: Apresentado ao TWG-PHC; posição registada sobre o diagnóstico; ata com comentários e responsáveis; alterações incorporadas em versão datada | D11: 46332 | E11: Não iniciada | F11: Estrutura analítica | G11: Documento estruturado pelas alavancas do operational framework; guias de entrevista mapeados nas alavancas; material das consultoras mapeado; forma de apresentação de barreiras, lacunas, gargalos e fortalezas definida | H11: 46276 | I11: Não iniciado | J11: Definir a forma de apresentação de barreiras, lacunas, gargalos e fortalezas | K11: S3 | L11: AGJ | M11: 1 | O11: Backlog
A12: HIIP | B12: Background document - PHC | C12: Apresentado ao TWG-PHC; posição registada sobre o diagnóstico; ata com comentários e responsáveis; alterações incorporadas em versão datada | D12: 46332 | E12: Não iniciada | F12: Espinha dorsal quantitativa | G12: Indicadores extraídos com data de extração; qualidade e completude avaliadas; anomalias listadas para interrogar no campo | H12: 46276 | I12: Não iniciado | J12: Extrair os indicadores do DHIS2 | K12: S3 | L12: AGJ | M12: 3 | O12: Backlog
A13: HIIP | B13: Background document - PHC | C13: Apresentado ao TWG-PHC; posição registada sobre o diagnóstico; ata com comentários e responsáveis; alterações incorporadas em versão datada | D13: 46332 | E13: Não iniciada | F13: Espinha dorsal quantitativa | G13: Indicadores extraídos com data de extração; qualidade e completude avaliadas; anomalias listadas para interrogar no campo | H13: 46276 | I13: Não iniciado | J13: Avaliar a qualidade e a completude dos dados extraídos | K13: S3 | L13: AGJ | M13: 2 | N13: Extração do DHIS2 | O13: Backlog
A14: HIIP | B14: Background document - PHC | C14: Apresentado ao TWG-PHC; posição registada sobre o diagnóstico; ata com comentários e responsáveis; alterações incorporadas em versão datada | D14: 46332 | E14: Não iniciada | F14: Espinha dorsal quantitativa | G14: Indicadores extraídos com data de extração; qualidade e completude avaliadas; anomalias listadas para interrogar no campo | H14: 46276 | I14: Não iniciado | J14: Identificar anomalias a interrogar no campo | K14: S3 | L14: AGJ | M14: 1 | N14: Avaliação de qualidade | O14: Backlog
A15: HIIP | B15: Background document - PHC | C15: Apresentado ao TWG-PHC; posição registada sobre o diagnóstico; ata com comentários e responsáveis; alterações incorporadas em versão datada | D15: 46332 | E15: Não iniciada | F15: Preparação das visitas piloto | G15: Anuência da DNSP registada; itens do HHFA selecionados com justificação; questionários testados no dispositivo antes da partida; lista de unidades e informantes acordada | H15: 46276 | I15: Não iniciado | J15: Pedir anuência à DNSP para as visitas e entrevistas piloto | K15: S3 | L15: AGJ | M15: 2 | O15: Backlog
A16: HIIP | B16: Background document - PHC | C16: Apresentado ao TWG-PHC; posição registada sobre o diagnóstico; ata com comentários e responsáveis; alterações incorporadas em versão datada | D16: 46332 | E16: Não iniciada | F16: Preparação das visitas piloto | G16: Anuência da DNSP registada; itens do HHFA selecionados com justificação; questionários testados no dispositivo antes da partida; lista de unidades e informantes acordada | H16: 46276 | I16: Não iniciado | J16: Selecionar do HHFA o que capturar neste piloto | K16: S3 | L16: AGJ | M16: 2 | O16: Backlog
A17: HIIP | B17: Background document - PHC | C17: Apresentado ao TWG-PHC; posição registada sobre o diagnóstico; ata com comentários e responsáveis; alterações incorporadas em versão datada | D17: 46332 | E17: Não iniciada | F17: Preparação das visitas piloto | G17: Anuência da DNSP registada; itens do HHFA selecionados com justificação; questionários testados no dispositivo antes da partida; lista de unidades e informantes acordada | H17: 46276 | I17: Não iniciado | J17: Preparar os questionários a partir do HHFA | K17: S3 | L17: AGJ | M17: 3 | N17: Seleção de itens do HHFA | O17: Backlog
A18: HIIP | B18: Background document - PHC | C18: Apresentado ao TWG-PHC; posição registada sobre o diagnóstico; ata com comentários e responsáveis; alterações incorporadas em versão datada | D18: 46332 | E18: Não iniciada | F18: Preparação das visitas piloto | G18: Anuência da DNSP registada; itens do HHFA selecionados com justificação; questionários testados no dispositivo antes da partida; lista de unidades e informantes acordada | H18: 46276 | I18: Não iniciado | J18: Carregar os questionários no KoboToolbox | K18: S3 | L18: AGJ | M18: 1 | N18: Questionários preparados | O18: Backlog
A19: HIIP | B19: Background document - PHC | C19: Apresentado ao TWG-PHC; posição registada sobre o diagnóstico; ata com comentários e responsáveis; alterações incorporadas em versão datada | D19: 46332 | E19: Não iniciada | F19: Preparação das visitas piloto | G19: Anuência da DNSP registada; itens do HHFA selecionados com justificação; questionários testados no dispositivo antes da partida; lista de unidades e informantes acordada | H19: 46276 | I19: Não iniciado | J19: Definir unidades, datas e perfis de informantes | K19: S3 | L19: AGJ | M19: 2 | N19: Anuência da DNSP | O19: Backlog
A20: HIIP | B20: Background document - PHC | C20: Apresentado ao TWG-PHC; posição registada sobre o diagnóstico; ata com comentários e responsáveis; alterações incorporadas em versão datada | D20: 46332 | E20: Não iniciada | F20: Visitas piloto realizadas | G20: Unidades previstas visitadas; dados sincronizados do Kobo; notas de entrevista transcritas; limitações do instrumento anotadas | H20: 46290 | I20: Não iniciado | J20: Conduzir as visitas às unidades sanitárias | K20: S4 | L20: AGJ | M20: 6 | N20: Preparação das visitas piloto | O20: Backlog
A21: HIIP | B21: Background document - PHC | C21: Apresentado ao TWG-PHC; posição registada sobre o diagnóstico; ata com comentários e responsáveis; alterações incorporadas em versão datada | D21: 46332 | E21: Não iniciada | F21: Visitas piloto realizadas | G21: Unidades previstas visitadas; dados sincronizados do Kobo; notas de entrevista transcritas; limitações do instrumento anotadas | H21: 46290 | I21: Não iniciado | J21: Conduzir entrevistas com profissionais e gestores locais, provinciais e nacionais | K21: S4 | L21: AGJ | M21: 4 | N21: Preparação das visitas piloto | O21: Backlog
A22: HIIP | B22: Background document - PHC | C22: Apresentado ao TWG-PHC; posição registada sobre o diagnóstico; ata com comentários e responsáveis; alterações incorporadas em versão datada | D22: 46332 | E22: Não iniciada | F22: Visitas piloto realizadas | G22: Unidades previstas visitadas; dados sincronizados do Kobo; notas de entrevista transcritas; limitações do instrumento anotadas | H22: 46290 | I22: Não iniciado | J22: Registar e organizar o material recolhido | K22: S4 | L22: AGJ | M22: 2 | N22: Visitas realizadas | O22: Backlog
A23: HIIP | B23: Background document - PHC | C23: Apresentado ao TWG-PHC; posição registada sobre o diagnóstico; ata com comentários e responsáveis; alterações incorporadas em versão datada | D23: 46332 | E23: Não iniciada | F23: Visitas piloto realizadas | G23: Unidades previstas visitadas; dados sincronizados do Kobo; notas de entrevista transcritas; limitações do instrumento anotadas | H23: 46290 | I23: Não iniciado | J23: Registar as lições do piloto para o desenho do HHFA | K23: S4 | L23: AGJ | M23: 1 | N23: Visitas realizadas | O23: Backlog
A24: HIIP | B24: Background document - PHC | C24: Apresentado ao TWG-PHC; posição registada sobre o diagnóstico; ata com comentários e responsáveis; alterações incorporadas em versão datada | D24: 46332 | E24: Não iniciada | F24: Síntese e mapeamento | G24: Achados codificados; barreiras, lacunas, gargalos e fortalezas classificados por estrutura, processo e resultado e mapeados nas alavancas; modelo de cuidados atual descrito; evidências dos informantes contrapostas à evidência científica atual | H24: 46304 | I24: Não iniciado | J24: Codificar e sintetizar os achados qualitativos | K24: S5 | L24: AGJ | M24: 4 | N24: Visitas piloto realizadas | O24: Backlog
A25: HIIP | B25: Background document - PHC | C25: Apresentado ao TWG-PHC; posição registada sobre o diagnóstico; ata com comentários e responsáveis; alterações incorporadas em versão datada | D25: 46332 | E25: Não iniciada | F25: Síntese e mapeamento | G25: Achados codificados; barreiras, lacunas, gargalos e fortalezas classificados por estrutura, processo e resultado e mapeados nas alavancas; modelo de cuidados atual descrito; evidências dos informantes contrapostas à evidência científica atual | H25: 46304 | I25: Não iniciado | J25: Mapear barreiras, lacunas, gargalos e fortalezas por estrutura, processo e resultado | K25: S5 | L25: AGJ | M25: 3 | N25: Síntese qualitativa | O25: Backlog
A26: HIIP | B26: Background document - PHC | C26: Apresentado ao TWG-PHC; posição registada sobre o diagnóstico; ata com comentários e responsáveis; alterações incorporadas em versão datada | D26: 46332 | E26: Não iniciada | F26: Síntese e mapeamento | G26: Achados codificados; barreiras, lacunas, gargalos e fortalezas classificados por estrutura, processo e resultado e mapeados nas alavancas; modelo de cuidados atual descrito; evidências dos informantes contrapostas à evidência científica atual | H26: 46304 | I26: Não iniciado | J26: Descrever o modelo de cuidados atual | K26: S5 | L26: AGJ | M26: 3 | N26: Síntese qualitativa | O26: Backlog
A27: HIIP | B27: Background document - PHC | C27: Apresentado ao TWG-PHC; posição registada sobre o diagnóstico; ata com comentários e responsáveis; alterações incorporadas em versão datada | D27: 46332 | E27: Não iniciada | F27: Síntese e mapeamento | G27: Achados codificados; barreiras, lacunas, gargalos e fortalezas classificados por estrutura, processo e resultado e mapeados nas alavancas; modelo de cuidados atual descrito; evidências dos informantes contrapostas à evidência científica atual | H27: 46304 | I27: Não iniciado | J27: Contrapor as evidências dos informantes à evidência científica atual | K27: S5 | L27: AGJ | M27: 3 | N27: Mapeamento | O27: Backlog
A28: HIIP | B28: Background document - PHC | C28: Apresentado ao TWG-PHC; posição registada sobre o diagnóstico; ata com comentários e responsáveis; alterações incorporadas em versão datada | D28: 46332 | E28: Não iniciada | F28: Background document v1 | G28: Forma de apresentação aplicada; secção de contraste escrita; linguagem adequada ao cliente; evidências e referências revistas; revisão do country office resolvida | H28: 46318 | I28: Não iniciado | J28: Redigir a secção de contraste entre o que se acredita e o que se observou | K28: S5 | L28: AGJ | M28: 2 | N28: Síntese e mapeamento | O28: Backlog
... A32: HIIP | B32: Background document - PHC | C32: Apresentado ao TWG-PHC; posição registada sobre o diagnóstico; ata com comentários e responsáveis; alterações incorporadas em versão datada | D32: 46332 | E32: Não iniciada | F32: Background document v1 | G32: Forma de apresentação aplicada; secção de contraste escrita; linguagem adequada ao cliente; evidências e referências revistas; revisão do country office resolvida | H32: 46318 | I32: Não iniciado | J32: Revisão do country office | K32: S6 | L32: AGJ | M32: 2 | N32: Background document v1 | O32: Backlog
A33: HIIP | B33: Background document - PHC | C33: Apresentado ao TWG-PHC; posição registada sobre o diagnóstico; ata com comentários e responsáveis; alterações incorporadas em versão datada | D33: 46332 | E33: Não iniciada | J33: Apresentar o documento ao TWG-PHC para validação | K33: S6 | L33: AGJ | M33: 1 | N33: TWG-PHC refundado; Background v1 | O33: Backlog
A34: HIIP | B34: Background document - PHC | C34: Apresentado ao TWG-PHC; posição registada sobre o diagnóstico; ata com comentários e responsáveis; alterações incorporadas em versão datada | D34: 46332 | E34: Não iniciada | J34: Incorporar os comentários do TWG-PHC | K34: S7 | L34: AGJ | M34: 2 | N34: Sessão de validação | O34: Backlog

Sheet 3. Strategy document
A1: Strategy document - PHC
A3: Projeto | B3: Frente de trabalho (produto) | C3: Validação externa | D3: Data validação | E3: Estado validação | F3: Resultado (output) | G3: Definição de feito (resultado) | H3: Data resultado | I3: Estado resultado | J3: Tarefa | K3: Sprint | L3: Responsável | M3: Estimativa (dias) | N3: Depende de | O3: Estado tarefa | P3: Aprendizado
